Traceback (most recent call last):
  File "/opt/homebrew/Caskroom/miniconda/base/envs/jupyter-book-env/lib/python3.10/site-packages/jupyter_cache/executors/utils.py", line 51, in single_nb_execution
    executenb(
  File "/opt/homebrew/Caskroom/miniconda/base/envs/jupyter-book-env/lib/python3.10/site-packages/nbclient/client.py", line 1204, in execute
    return NotebookClient(nb=nb, resources=resources, km=km, **kwargs).execute()
  File "/opt/homebrew/Caskroom/miniconda/base/envs/jupyter-book-env/lib/python3.10/site-packages/nbclient/util.py", line 84, in wrapped
    return just_run(coro(*args, **kwargs))
  File "/opt/homebrew/Caskroom/miniconda/base/envs/jupyter-book-env/lib/python3.10/site-packages/nbclient/util.py", line 62, in just_run
    return loop.run_until_complete(coro)
  File "/opt/homebrew/Caskroom/miniconda/base/envs/jupyter-book-env/lib/python3.10/asyncio/base_events.py", line 649, in run_until_complete
    return future.result()
  File "/opt/homebrew/Caskroom/miniconda/base/envs/jupyter-book-env/lib/python3.10/site-packages/nbclient/client.py", line 663, in async_execute
    await self.async_execute_cell(
  File "/opt/homebrew/Caskroom/miniconda/base/envs/jupyter-book-env/lib/python3.10/site-packages/nbclient/client.py", line 965, in async_execute_cell
    await self._check_raise_for_error(cell, cell_index, exec_reply)
  File "/opt/homebrew/Caskroom/miniconda/base/envs/jupyter-book-env/lib/python3.10/site-packages/nbclient/client.py", line 862, in _check_raise_for_error
    raise CellExecutionError.from_cell_and_msg(cell, exec_reply_content)
nbclient.exceptions.CellExecutionError: An error occurred while executing the following cell:
------------------
FRECUENCY = 5.0 # Hertz
#print(t)
x1 = AMPL*np.sin(2 * np.pi * FRECUENCY * t + PHASE)
#print(y)

# Plot de la senal
fig1, ax1 = plt.subplots()
ax1.set_xlabel("Tiempo", fontsize=16)
ax1.set_ylabel("Amplitud", fontsize=16)
ax1.grid(True)
ax1.stem(t, x1,use_line_collection = True)
------------------

[0;31m---------------------------------------------------------------------------[0m
[0;31mTypeError[0m                                 Traceback (most recent call last)
Cell [0;32mIn[6], line 11[0m
[1;32m      9[0m ax1[38;5;241m.[39mset_ylabel([38;5;124m"[39m[38;5;124mAmplitud[39m[38;5;124m"[39m, fontsize[38;5;241m=[39m[38;5;241m16[39m)
[1;32m     10[0m ax1[38;5;241m.[39mgrid([38;5;28;01mTrue[39;00m)
[0;32m---> 11[0m [43max1[49m[38;5;241;43m.[39;49m[43mstem[49m[43m([49m[43mt[49m[43m,[49m[43m [49m[43mx1[49m[43m,[49m[43muse_line_collection[49m[43m [49m[38;5;241;43m=[39;49m[43m [49m[38;5;28;43;01mTrue[39;49;00m[43m)[49m

File [0;32m/opt/homebrew/Caskroom/miniconda/base/envs/jupyter-book-env/lib/python3.10/site-packages/matplotlib/__init__.py:1465[0m, in [0;36m_preprocess_data.<locals>.inner[0;34m(ax, data, *args, **kwargs)[0m
[1;32m   1462[0m [38;5;129m@functools[39m[38;5;241m.[39mwraps(func)
[1;32m   1463[0m [38;5;28;01mdef[39;00m [38;5;21minner[39m(ax, [38;5;241m*[39margs, data[38;5;241m=[39m[38;5;28;01mNone[39;00m, [38;5;241m*[39m[38;5;241m*[39mkwargs):
[1;32m   1464[0m     [38;5;28;01mif[39;00m data [38;5;129;01mis[39;00m [38;5;28;01mNone[39;00m:
[0;32m-> 1465[0m         [38;5;28;01mreturn[39;00m [43mfunc[49m[43m([49m[43max[49m[43m,[49m[43m [49m[38;5;241;43m*[39;49m[38;5;28;43mmap[39;49m[43m([49m[43msanitize_sequence[49m[43m,[49m[43m [49m[43margs[49m[43m)[49m[43m,[49m[43m [49m[38;5;241;43m*[39;49m[38;5;241;43m*[39;49m[43mkwargs[49m[43m)[49m
[1;32m   1467[0m     bound [38;5;241m=[39m new_sig[38;5;241m.[39mbind(ax, [38;5;241m*[39margs, [38;5;241m*[39m[38;5;241m*[39mkwargs)
[1;32m   1468[0m     auto_label [38;5;241m=[39m (bound[38;5;241m.[39marguments[38;5;241m.[39mget(label_namer)
[1;32m   1469[0m                   [38;5;129;01mor[39;00m bound[38;5;241m.[39mkwargs[38;5;241m.[39mget(label_namer))

[0;31mTypeError[0m: Axes.stem() got an unexpected keyword argument 'use_line_collection'
TypeError: Axes.stem() got an unexpected keyword argument 'use_line_collection'

